Workbook

Sheet Assumptions
A1: AeroDesk — Key Assumptions (v2.0)
B2: Year 0 | C2: Year 1 | D2: Year 2 | E2: Year 3 | F2: Year 4 | G2: Year 5 | H2: Notes
A3: MARKET
A4: Global Used Aircraft Mkt (USD B) | C4: 40.07 | D4: =C4*(1+$C$5) -> 42.862879 | E4: =D4*(1+$C$5) -> 45.850422 | F4: =E4*(1+$C$5) -> 49.046196 | G4: =F4*(1+$C$5) -> 52.464716 | H4: MRFR 2025
A5: Market CAGR | C5: 0.0697
A6: Brazil Exec Aircraft Fleet | C6: 10060 | D6: =ROUND(C6*(1+$C$7),0) -> 10301 | E6: =ROUND(D6*(1+$C$7),0) -> 10548 | F6: =ROUND(E6*(1+$C$7),0) -> 10801 | G6: =ROUND(F6*(1+$C$7),0) -> 11060 | H6: ANAC 9824+2.4%
A7: Brazil Fleet Growth | C7: 0.024
A8: Online Aircraft Mktplace TAM (USD M) | C8: 800 | D8: =ROUND(C8*(1+$C$5),0) -> 856 | E8: =ROUND(D8*(1+$C$5),0) -> 916 | F8: =ROUND(E8*(1+$C$5),0) -> 980 | G8: =ROUND(F8*(1+$C$5),0) -> 1048 | H8: ~2% of total mkt
A10: PLATFORM KPIs
A11: Active Dealer Subscribers | B11: 0 | C11: 40 | D11: 150 | E11: 380 | F11: 650 | G11: 1000
A12: Total Active Listings | B12: 0 | C12: 600 | D12: 2200 | E12: 5500 | F12: 10000 | G12: 18000
A13: Monthly Unique Visitors | B13: 0 | C13: 25000 | D13: 120000 | E13: 400000 | F13: 800000 | G13: 1500000
A14: Avg Listing Value (USD) | C14: 850000 | D14: 900000 | E14: 950000 | F14: 1000000 | G14: 1050000 | H14: Blended avg
A15: Transactions Facilitated | B15: 0 | C15: 15 | D15: 80 | E15: 250 | F15: 550 | G15: 1100 | H15: Via escrow/finance
A17: REVENUE ASSUMPTIONS
A18: Avg Dealer Subscription ($/mo) | C18: 180 | D18: 220 | E18: 260 | F18: 300 | G18: 340 | H18: Blended tiers
A19: Featured Listing Fee (avg $) | C19: 350 | D19: 400 | E19: 450 | F19: 500 | G19: 550
A20: Featured Listings Sold/Yr | B20: 0 | C20: 120 | D20: 450 | E20: 1100 | F20: 2000 | G20: 3500
A21: Individual Listing Fee (avg $) | C21: 80 | D21: 90 | E21: 100 | F21: 110 | G21: 120
A22: Individual Listings Sold/Yr | B22: 0 | C22: 200 | D22: 800 | E22: 2000 | F22: 4000 | G22: 7000
A23: Transaction Commission Rate (capped 1% Y3+) | B23: 0 | C23: 0.005 | D23: 0.008 | E23: 0.01 | F23: 0.01 | G23: 0.01
A24: Insurance Referral ($/policy) | C24: 500 | D24: 600 | E24: 700 | F24: 750 | G24: 800
A25: Insurance Policies Referred | B25: 0 | C25: 10 | D25: 50 | E25: 180 | F25: 400 | G25: 800
A26: PPI Referral ($) | C26: 800 | D26: 900 | E26: 1000 | F26: 1000 | G26: 1000
A27: PPI Referrals/Yr | B27: 0 | C27: 10 | D27: 60 | E27: 200 | F27: 450 | G27: 900
A28: Legal Referral ($) | C28: 400 | D28: 500 | E28: 600 | F28: 650 | G28: 700
A29: Legal Referrals/Yr | B29: 0 | C29: 8 | D29: 45 | E29: 150 | F29: 350 | G29: 700
A30: Data Analytics Subscribers | B30: 0 | C30: 10 | D30: 40 | E30: 100 | F30: 200 | G30: 350
A31: Data Subscription ($/mo) | C31: 250 | D31: 300 | E31: 350 | F31: 400 | G31: 450
A32: MARKETING / ADVERTISING
A33: Brand Advertisers (monthly) | B33: 0 | C33: 3 | D33: 12 | E33: 30 | F33: 55 | G33: 90 | H33: OEMs, MROs, brokers
A34: Avg Ad Package ($/mo) | C34: 1500 | D34: 2000 | E34: 2500 | F34: 3000 | G34: 3500 | H34: Banner+newsletter+featured
A36: COST ASSUMPTIONS
A37: Headcount | B37: 2 | C37: 8 | D37: 14 | E37: 22 | F37: 32 | G37: 45
A38: Avg Salary+Benefits ($/yr) | C38: 60000 | D38: 65000 | E38: 70000 | F38: 75000 | G38: 80000 | H38: Brazil-weighted
A39: Cloud Infra ($/mo) | B39: 500 | C39: 2000 | D39: 4500 | E39: 8000 | F39: 14000 | G39: 22000 | H39: AWS/Vercel/CDN
A40: Marketing as % of Revenue | C40: 0.55 | D40: 0.4 | E40: 0.3 | F40: 0.22 | G40: 0.18 | H40: Declining as organic grows
A41: Tax Rate | C41: 0.15 | D41: 0.15 | E41: 0.15 | F41: 0.15 | G41: 0.15
A42: Depreciation Rate (% PP&E) | C42: 0.2 | D42: 0.2 | E42: 0.2 | F42: 0.2 | G42: 0.2
A43: Capex (USD) | B43: 350000 | C43: 180000 | D43: 250000 | E43: 200000 | F43: 300000 | G43: 400000 | H43: Tech+office
...

Sheet Revenue Detail
A1: AeroDesk — Revenue Build-Up (USD)
B2: Year 0 | C2: Year 1 | D2: Year 2 | E2: Year 3 | F2: Year 4 | G2: Year 5 | H2: Notes
A3: 1. DEALER SUBSCRIPTIONS
A4: Subscribers | B4: =Assumptions!B11 -> 0 | C4: =Assumptions!C11 -> 40 | D4: =Assumptions!D11 -> 150 | E4: =Assumptions!E11 -> 380 | F4: =Assumptions!F11 -> 650 | G4: =Assumptions!G11 -> 1000
A5: Avg Monthly Fee | C5: =Assumptions!C18 -> 180 | D5: =Assumptions!D18 -> 220 | E5: =Assumptions!E18 -> 260 | F5: =Assumptions!F18 -> 300 | G5: =Assumptions!G18 -> 340
A6: Dealer Subscription Revenue | B6: 0 | C6: =C4*C5*12 -> 86400 | D6: =D4*D5*12 -> 396000 | E6: =E4*E5*12 -> 1185600 | F6: =F4*F5*12 -> 2340000 | G6: =G4*G5*12 -> 4080000
A8: 2. FEATURED LISTINGS
A9: Qty Sold | B9: =Assumptions!B20 -> 0 | C9: =Assumptions!C20 -> 120 | D9: =Assumptions!D20 -> 450 | E9: =Assumptions!E20 -> 1100 | F9: =Assumptions!F20 -> 2000 | G9: =Assumptions!G20 -> 3500
A10: Avg Fee | C10: =Assumptions!C19 -> 350 | D10: =Assumptions!D19 -> 400 | E10: =Assumptions!E19 -> 450 | F10: =Assumptions!F19 -> 500 | G10: =Assumptions!G19 -> 550
A11: Featured Listing Revenue | B11: 0 | C11: =C9*C10 -> 42000 | D11: =D9*D10 -> 180000 | E11: =E9*E10 -> 495000 | F11: =F9*F10 -> 1000000 | G11: =G9*G10 -> 1925000
A13: 3. INDIVIDUAL LISTINGS
A14: Qty Sold | B14: =Assumptions!B22 -> 0 | C14: =Assumptions!C22 -> 200 | D14: =Assumptions!D22 -> 800 | E14: =Assumptions!E22 -> 2000 | F14: =Assumptions!F22 -> 4000 | G14: =Assumptions!G22 -> 7000
A15: Avg Fee | C15: =Assumptions!C21 -> 80 | D15: =Assumptions!D21 -> 90 | E15: =Assumptions!E21 -> 100 | F15: =Assumptions!F21 -> 110 | G15: =Assumptions!G21 -> 120
A16: Individual Listing Revenue | B16: 0 | C16: =C14*C15 -> 16000 | D16: =D14*D15 -> 72000 | E16: =E14*E15 -> 200000 | F16: =F14*F15 -> 440000 | G16: =G14*G15 -> 840000
A18: 4. TRANSACTION COMMISSIONS (capped 1% Y3+)
A19: Transactions | B19: =Assumptions!B15 -> 0 | C19: =Assumptions!C15 -> 15 | D19: =Assumptions!D15 -> 80 | E19: =Assumptions!E15 -> 250 | F19: =Assumptions!F15 -> 550 | G19: =Assumptions!G15 -> 1100
A20: Avg Value | C20: =Assumptions!C14 -> 850000 | D20: =Assumptions!D14 -> 900000 | E20: =Assumptions!E14 -> 950000 | F20: =Assumptions!F14 -> 1000000 | G20: =Assumptions!G14 -> 1050000
A21: Commission Rate | C21: =Assumptions!C23 -> 0.005 | D21: =Assumptions!D23 -> 0.008 | E21: =Assumptions!E23 -> 0.01 | F21: =Assumptions!F23 -> 0.01 | G21: =Assumptions!G23 -> 0.01
A22: Transaction Commission Revenue | B22: 0 | C22: =C19*C20*C21 -> 63750 | D22: =D19*D20*D21 -> 576000 | E22: =E19*E20*E21 -> 2375000 | F22: =F19*F20*F21 -> 5500000 | G22: =G19*G20*G21 -> 11550000
A24: 5. ANCILLARY SERVICES
A25: Insurance Referral Rev | B25: 0 | C25: =Assumptions!C24*Assumptions!C25 -> 5000 | D25: =Assumptions!D24*Assumptions!D25 -> 30000 | E25: =Assumptions!E24*Assumptions!E25 -> 126000 | F25: =Assumptions!F24*Assumptions!F25 -> 300000 | G25: =Assumptions!G24*Assumptions!G25 -> 640000
A26: PPI Referral Rev | B26: 0 | C26: =Assumptions!C26*Assumptions!C27 -> 8000 | D26: =Assumptions!D26*Assumptions!D27 -> 54000 | E26: =Assumptions!E26*Assumptions!E27 -> 200000 | F26: =Assumptions!F26*Assumptions!F27 -> 450000 | G26: =Assumptions!G26*Assumptions!G27 -> 900000
A27: Legal Referral Rev | B27: 0 | C27: =Assumptions!C28*Assumptions!C29 -> 3200 | D27: =Assumptions!D28*Assumptions!D29 -> 22500 | E27: =Assumptions!E28*Assumptions!E29 -> 90000 | F27: =Assumptions!F28*Assumptions!F29 -> 227500 | G27: =Assumptions!G28*Assumptions!G29 -> 490000
A28: Total Ancillary Revenue | B28: 0 | C28: =SUM(C25:C27) -> 16200 | D28: =SUM(D25:D27) -> 106500 | E28: =SUM(E25:E27) -> 416000 | F28: =SUM(F25:F27) -> 977500 | G28: =SUM(G25:G27) -> 2030000
A30: 6. DATA & ANALYTICS
A31: Subscribers | B31: =Assumptions!B30 -> 0 | C31: =Assumptions!C30 -> 10 | D31: =Assumptions!D30 -> 40 | E31: =Assumptions!E30 -> 100 | F31: =Assumptions!F30 -> 200 | G31: =Assumptions!G30 -> 350
A32: Monthly Fee | C32: =Assumptions!C31 -> 250 | D32: =Assumptions!D31 -> 300 | E32: =Assumptions!E31 -> 350 | F32: =Assumptions!F31 -> 400 | G32: =Assumptions!G31 -> 450
A33: Data & Analytics Revenue | B33: 0 | C33: =C31*C32*12 -> 30000 | D33: =D31*D32*12 -> 144000 | E33: =E31*E32*12 -> 420000 | F33: =F31*F32*12 -> 960000 | G33: =G31*G32*12 -> 1890000
A35: 7. MARKETING / ADVERTISING REVENUE
A36: Brand Advertisers | B36: =Assumptions!B33 -> 0 | C36: =Assumptions!C33 -> 3 | D36: =Assumptions!D33 -> 12 | E36: =Assumptions!E33 -> 30 | F36: =Assumptions!F33 -> 55 | G36: =Assumptions!G33 -> 90
A37: Avg Package ($/mo) | C37: =Assumptions!C34 -> 1500 | D37: =Assumptions!D34 -> 2000 | E37: =Assumptions!E34 -> 2500 | F37: =Assumptions!F34 -> 3000 | G37: =Assumptions!G34 -> 3500
A38: Marketing / Ad Revenue | B38: 0 | C38: =C36*C37*12 -> 54000 | D38: =D36*D37*12 -> 288000 | E38: =E36*E37*12 -> 900000 | F38: =F36*F37*12 -> 1980000 | G38: =G36*G37*12 -> 3780000
A40: TOTAL REVENUE
A41: TOTAL REVENUE | B41: 0 | C41: =C6+C11+C16+C22+C28+C33+C38 -> 308350 | D41: =D6+D11+D16+D22+D28+D33+D38 -> 1762500 | E41: =E6+E11+E16+E22+E28+E33+E38 -> 5991600 | F41: =F6+F11+F16+F22+F28+F33+F38 -> 13197500 | G41: =G6+G11+G16+G22+G28+G33+G38 -> 26095000
A43: Revenue Mix (%)
A44: Dealer Subs % | C44: =IF(C41=0,0,C6/C41) -> 0.28020107 | D44: =IF(D41=0,0,D6/D41) -> 0.22468085 | E44: =IF(E41=0,0,E6/E41) -> 0.19787703 | F44: =IF(F41=0,0,F6/F41) -> 0.17730631 | G44: =IF(G41=0,0,G6/G41) -> 0.15635179
A45: Featured % | C45: =IF(C41=0,0,C11/C41) -> 0.13620885 | D45: =IF(D41=0,0,D11/D41) -> 0.10212766 | E45: =IF(E41=0,0,E11/E41) -> 0.082615662 | F45: =IF(F41=0,0,F11/F41) -> 0.075771927 | G45: =IF(G41=0,0,G11/G41) -> 0.073768921
A46: Individual % | C46: =IF(C41=0,0,C16/C41) -> 0.051889087 | D46: =IF(D41=0,0,D16/D41) -> 0.040851064 | E46: =IF(E41=0,0,E16/E41) -> 0.033380065 | F46: =IF(F41=0,0,F16/F41) -> 0.033339648 | G46: =IF(G41=0,0,G16/G41) -> 0.032190075
A47: Txn Commissions % | C47: =IF(C41=0,0,C22/C41) -> 0.20674558 | D47: =IF(D41=0,0,D22/D41) -> 0.32680851 | E47: =IF(E41=0,0,E22/E41) -> 0.39638828 | F47: =IF(F41=0,0,F22/F41) -> 0.4167456 | G47: =IF(G41=0,0,G22/G41) -> 0.44261353
A48: Ancillary % | C48: =IF(C41=0,0,C28/C41) -> 0.052537701 | D48: =IF(D41=0,0,D28/D41) -> 0.060425532 | E48: =IF(E41=0,0,E28/E41) -> 0.069430536 | F48: =IF(F41=0,0,F28/F41) -> 0.074067058 | G48: =IF(G41=0,0,G28/G41) -> 0.077792681
...

Sheet Income Statement
A1: AeroDesk — Income Statement (USD)
B2: Year 0 | C2: Year 1 | D2: Year 2 | E2: Year 3 | F2: Year 4 | G2: Year 5 | H2: Notes
A3: REVENUE
A4: Total Revenue | B4: ='Revenue Detail'!B41 -> 0 | C4: ='Revenue Detail'!C41 -> 308350 | D4: ='Revenue Detail'!D41 -> 1762500 | E4: ='Revenue Detail'!E41 -> 5991600 | F4: ='Revenue Detail'!F41 -> 13197500 | G4: ='Revenue Detail'!G41 -> 26095000
A6: COGS
A7: Payment Processing (2.5% Rev) | B7: 0 | C7: =C4*0.025 -> 7708.75 | D7: =D4*0.025 -> 44062.5 | E7: =E4*0.025 -> 149790 | F7: =F4*0.025 -> 329937.5 | G7: =G4*0.025 -> 652375
A8: Cloud Infrastructure | B8: =Assumptions!B39*12 -> 6000 | C8: =Assumptions!C39*12 -> 24000 | D8: =Assumptions!D39*12 -> 54000 | E8: =Assumptions!E39*12 -> 96000 | F8: =Assumptions!F39*12 -> 168000 | G8: =Assumptions!G39*12 -> 264000
A9: Data Licensing & APIs | B9: 0 | C9: 12000 | D9: 24000 | E9: 36000 | F9: 48000 | G9: 60000
A10: Customer Support | B10: 0 | C10: 24000 | D10: 48000 | E10: 84000 | F10: 144000 | G10: 240000
A11: Total COGS | B11: =SUM(B7:B10) -> 6000 | C11: =SUM(C7:C10) -> 67708.75 | D11: =SUM(D7:D10) -> 170062.5 | E11: =SUM(E7:E10) -> 365790 | F11: =SUM(F7:F10) -> 689937.5 | G11: =SUM(G7:G10) -> 1216375
A12: Gross Profit | B12: =B4-B11 -> -6000 | C12: =C4-C11 -> 240641.25 | D12: =D4-D11 -> 1592437.5 | E12: =E4-E11 -> 5625810 | F12: =F4-F11 -> 12507562 | G12: =G4-G11 -> 24878625
A13: Gross Margin % | C13: =IF(C4=0,0,C12/C4) -> 0.78041592 | D13: =IF(D4=0,0,D12/D4) -> 0.90351064 | E13: =IF(E4=0,0,E12/E4) -> 0.93894953 | F13: =IF(F4=0,0,F12/F4) -> 0.94772211 | G13: =IF(G4=0,0,G12/G4) -> 0.95338666
A15: SG&A
A16: Salaries & Benefits | B16: =Assumptions!B37*Assumptions!B38 -> 0 | C16: =Assumptions!C37*Assumptions!C38 -> 480000 | D16: =Assumptions!D37*Assumptions!D38 -> 910000 | E16: =Assumptions!E37*Assumptions!E38 -> 1540000 | F16: =Assumptions!F37*Assumptions!F38 -> 2400000 | G16: =Assumptions!G37*Assumptions!G38 -> 3600000
A17: Marketing & Acquisition | B17: 30000 | C17: =MAX(C4*Assumptions!C40,60000) -> 169592.5 | D17: =MAX(D4*Assumptions!D40,60000) -> 705000 | E17: =MAX(E4*Assumptions!E40,60000) -> 1797480 | F17: =MAX(F4*Assumptions!F40,60000) -> 2903450 | G17: =MAX(G4*Assumptions!G40,60000) -> 4697100
A18: Office & Co-working | B18: 6000 | C18: 24000 | D18: 36000 | E18: 60000 | F18: 96000 | G18: 144000
A19: Professional Services | B19: 15000 | C19: 30000 | D19: 48000 | E19: 72000 | F19: 96000 | G19: 120000
A20: Software & Tools | B20: 3000 | C20: 18000 | D20: 30000 | E20: 48000 | F20: 72000 | G20: 96000
A21: Travel & Events | B21: 5000 | C21: 30000 | D21: 48000 | E21: 72000 | F21: 96000 | G21: 120000
A22: D&O Insurance | B22: 0 | C22: 12000 | D22: 18000 | E22: 24000 | F22: 36000 | G22: 48000
A23: Total SG&A | B23: =SUM(B16:B22) -> 59000 | C23: =SUM(C16:C22) -> 763592.5 | D23: =SUM(D16:D22) -> 1795000 | E23: =SUM(E16:E22) -> 3613480 | F23: =SUM(F16:F22) -> 5699450 | G23: =SUM(G16:G22) -> 8825100
A25: EBITDA | B25: =B12-B23 -> -65000 | C25: =C12-C23 -> -522951.25 | D25: =D12-D23 -> -202562.5 | E25: =E12-E23 -> 2012330 | F25: =F12-F23 -> 6808112.5 | G25: =G12-G23 -> 16053525
A26: EBITDA Margin % | C26: =IF(C4=0,0,C25/C4) -> -1.6959664 | D26: =IF(D4=0,0,D25/D4) -> -0.11492908 | E26: =IF(E4=0,0,E25/E4) -> 0.33585854 | F26: =IF(F4=0,0,F25/F4) -> 0.5158638 | G26: =IF(G4=0,0,G25/G4) -> 0.61519544
A28: D&A | B28: =Assumptions!B43*Assumptions!B42 -> 0 | C28: =Assumptions!C43*Assumptions!C42 -> 36000 | D28: =Assumptions!D43*Assumptions!D42 -> 50000 | E28: =Assumptions!E43*Assumptions!E42 -> 40000 | F28: =Assumptions!F43*Assumptions!F42 -> 60000 | G28: =Assumptions!G43*Assumptions!G42 -> 80000
A29: EBIT | B29: =B25-B28 -> -65000 | C29: =C25-C28 -> -558951.25 | D29: =D25-D28 -> -252562.5 | E29: =E25-E28 -> 1972330 | F29: =F25-F28 -> 6748112.5 | G29: =G25-G28 -> 15973525
A30: Interest | B30: 0 | C30: 0 | D30: 0 | E30: 0 | F30: 0 | G30: 0
A31: EBT | B31: =B29-B30 -> -65000 | C31: =C29-C30 -> -558951.25 | D31: =D29-D30 -> -252562.5 | E31: =E29-E30 -> 1972330 | F31: =F29-F30 -> 6748112.5 | G31: =G29-G30 -> 15973525
A32: Taxes | B32: 0 | C32: =IF(C31>0,C31*Assumptions!C41,0) -> 0 | D32: =IF(D31>0,D31*Assumptions!D41,0) -> 0 | E32: =IF(E31>0,E31*Assumptions!E41,0) -> 295849.5 | F32: =IF(F31>0,F31*Assumptions!F41,0) -> 1012216.9 | G32: =IF(G31>0,G31*Assumptions!G41,0) -> 2396028.8
A33: NET INCOME | B33: =B31-B32 -> -65000 | C33: =C31-C32 -> -558951.25 | D33: =D31-D32 -> -252562.5 | E33: =E31-E32 -> 1676480.5 | F33: =F31-F32 -> 5735895.6 | G33: =G31-G32 -> 13577496
A34: Net Margin % | C34: =IF(C4=0,0,C33/C4) -> -1.8127169 | D34: =IF(D4=0,0,D33/D4) -> -0.14329787 | E34: =IF(E4=0,0,E33/E4) -> 0.27980514 | F34: =IF(F4=0,0,F33/F4) -> 0.43461986 | G34: =IF(G4=0,0,G33/G4) -> 0.52031026

Sheet Balance Sheet
A1: AeroDesk — Balance Sheet (USD)
B2: Year 0 | C2: Year 1 | D2: Year 2 | E2: Year 3 | F2: Year 4 | G2: Year 5 | H2: Notes
A3: ASSETS
A4: Cash | B4: ='Cash Flow'!B20 -> 475000 | C4: ='Cash Flow'!C20 -> -265879.32 | D4: ='Cash Flow'!D20 -> -918005.94 | E4: ='Cash Flow'!E20 -> -31909.5 | F4: ='Cash Flow'!F20 -> 4368521.2 | G4: ='Cash Flow'!G20 -> 15632239
A5: Accounts Receivable | B5: 0 | C5: ='Income Statement'!C4/12*2 -> 51391.667 | D5: ='Income Statement'!D4/12*2 -> 293750 | E5: ='Income Statement'!E4/12*2 -> 998600 | F5: ='Income Statement'!F4/12*2 -> 2199583.3 | G5: ='Income Statement'!G4/12*2 -> 4349166.7
A6: Prepaid Expenses | B6: 10000 | C6: 20000 | D6: 30000 | E6: 40000 | F6: 50000 | G6: 60000
A7: Current Assets | B7: =SUM(B4:B6) -> 485000 | C7: =SUM(C4:C6) -> -194487.66 | D7: =SUM(D4:D6) -> -594255.94 | E7: =SUM(E4:E6) -> 1006690.5 | F7: =SUM(F4:F6) -> 6618104.6 | G7: =SUM(G4:G6) -> 20041406
A9: PP&E (Net) | B9: =Assumptions!B43 -> 350000 | C9: =B9+Assumptions!C43-'Income Statement'!C28 -> 494000 | D9: =C9+Assumptions!D43-'Income Statement'!D28 -> 694000 | E9: =D9+Assumptions!E43-'Income Statement'!E28 -> 854000 | F9: =E9+Assumptions!F43-'Income Statement'!F28 -> 1094000 | G9: =F9+Assumptions!G43-'Income Statement'!G28 -> 1414000
A10: TOTAL ASSETS | B10: =B7+B9 -> 835000 | C10: =C7+C9 -> 299512.34 | D10: =D7+D9 -> 99744.062 | E10: =E7+E9 -> 1860690.5 | F10: =F7+F9 -> 7712104.6 | G10: =G7+G9 -> 21455406
A12: LIABILITIES
A13: Accounts Payable | B13: 15000 | C13: ='Income Statement'!C11/12*1.5 -> 8463.5938 | D13: ='Income Statement'!D11/12*1.5 -> 21257.812 | E13: ='Income Statement'!E11/12*1.5 -> 45723.75 | F13: ='Income Statement'!F11/12*1.5 -> 86242.188 | G13: ='Income Statement'!G11/12*1.5 -> 152046.88
A14: Deferred Revenue | B14: 0 | C14: 15000 | D14: 40000 | E14: 80000 | F14: 130000 | G14: 200000
A15: Accrued Expenses | B15: 5000 | C15: 20000 | D15: 35000 | E15: 55000 | F15: 80000 | G15: 110000
A16: Total Liabilities | B16: =SUM(B13:B15) -> 20000 | C16: =SUM(C13:C15) -> 43463.594 | D16: =SUM(D13:D15) -> 96257.812 | E16: =SUM(E13:E15) -> 180723.75 | F16: =SUM(F13:F15) -> 296242.19 | G16: =SUM(G13:G15) -> 462046.88
A18: EQUITY
A19: Paid-in Capital | B19: =Assumptions!$B$44 -> 920000 | C19: =Assumptions!$B$44 -> 920000 | D19: =Assumptions!$B$44 -> 920000 | E19: =Assumptions!$B$44 -> 920000 | F19: =Assumptions!$B$44 -> 920000 | G19: =Assumptions!$B$44 -> 920000
A20: Retained Earnings | B20: 0 | C20: =B20+'Income Statement'!C33 -> -558951.25 | D20: =C20+'Income Statement'!D33 -> -811513.75 | E20: =D20+'Income Statement'!E33 -> 864966.75 | F20: =E20+'Income Statement'!F33 -> 6600862.4 | G20: =F20+'Income Statement'!G33 -> 20178359
A21: Total Equity | B21: =B19+B20 -> 920000 | C21: =C19+C20 -> 361048.75 | D21: =D19+D20 -> 108486.25 | E21: =E19+E20 -> 1784966.8 | F21: =F19+F20 -> 7520862.4 | G21: =G19+G20 -> 21098359
A23: TOTAL L+E | B23: =B16+B21 -> 940000 | C23: =C16+C21 -> 404512.34 | D23: =D16+D21 -> 204744.06 | E23: =E16+E21 -> 1965690.5 | F23: =F16+F21 -> 7817104.6 | G23: =G16+G21 -> 21560406
A25: Balance Check | B25: =B10-B23 -> -105000 | C25: =C10-C23 -> -105000 | D25: =D10-D23 -> -105000 | E25: =E10-E23 -> -105000 | F25: =F10-F23 -> -105000 | G25: =G10-G23 -> -105000

Sheet Cash Flow
A1: AeroDesk — Cash Flow Statement (USD)
B2: Year 0 | C2: Year 1 | D2: Year 2 | E2: Year 3 | F2: Year 4 | G2: Year 5 | H2: Notes
A3: OPERATING
A4: Net Income | B4: ='Income Statement'!B33 -> -65000 | C4: ='Income Statement'!C33 -> -558951.25 | D4: ='Income Statement'!D33 -> -252562.5 | E4: ='Income Statement'!E33 -> 1676480.5 | F4: ='Income Statement'!F33 -> 5735895.6 | G4: ='Income Statement'!G33 -> 13577496
A5: (+) D&A | B5: ='Income Statement'!B28 -> 0 | C5: ='Income Statement'!C28 -> 36000 | D5: ='Income Statement'!D28 -> 50000 | E5: ='Income Statement'!E28 -> 40000 | F5: ='Income Statement'!F28 -> 60000 | G5: ='Income Statement'!G28 -> 80000
A6: WC Changes | B6: -30000 | C6: =-('Balance Sheet'!C5-'Balance Sheet'!B5)+('Balance Sheet'!C13-'Balance Sheet'!B13)+('Balance Sheet'!C14-'Balance Sheet'!B14)+('Balance Sheet'!C15-'Balance Sheet'!B15)-('Balance Sheet'!C6-'Balance Sheet'!B6) -> -37928.073 | D6: =-('Balance Sheet'!D5-'Balance Sheet'!C5)+('Balance Sheet'!D13-'Balance Sheet'!C13)+('Balance Sheet'!D14-'Balance Sheet'!C14)+('Balance Sheet'!D15-'Balance Sheet'!C15)-('Balance Sheet'!D6-'Balance Sheet'!C6) -> -199564.11 | E6: =-('Balance Sheet'!E5-'Balance Sheet'!D5)+('Balance Sheet'!E13-'Balance Sheet'!D13)+('Balance Sheet'!E14-'Balance Sheet'!D14)+('Balance Sheet'!E15-'Balance Sheet'!D15)-('Balance Sheet'!E6-'Balance Sheet'!D6) -> -630384.06 | F6: =-('Balance Sheet'!F5-'Balance Sheet'!E5)+('Balance Sheet'!F13-'Balance Sheet'!E13)+('Balance Sheet'!F14-'Balance Sheet'!E14)+('Balance Sheet'!F15-'Balance Sheet'!E15)-('Balance Sheet'!F6-'Balance Sheet'!E6) -> -1095464.9 | G6: =-('Balance Sheet'!G5-'Balance Sheet'!F5)+('Balance Sheet'!G13-'Balance Sheet'!F13)+('Balance Sheet'!G14-'Balance Sheet'!F14)+('Balance Sheet'!G15-'Balance Sheet'!F15)-('Balance Sheet'!G6-'Balance Sheet'!F6) -> -1993778.6
A7: Cash from Operations | B7: =SUM(B4:B6) -> -95000 | C7: =SUM(C4:C6) -> -560879.32 | D7: =SUM(D4:D6) -> -402126.61 | E7: =SUM(E4:E6) -> 1086096.4 | F7: =SUM(F4:F6) -> 4700430.7 | G7: =SUM(G4:G6) -> 11663718
A9: INVESTING
A10: Capex | B10: =-Assumptions!B43 -> -350000 | C10: =-Assumptions!C43 -> -180000 | D10: =-Assumptions!D43 -> -250000 | E10: =-Assumptions!E43 -> -200000 | F10: =-Assumptions!F43 -> -300000 | G10: =-Assumptions!G43 -> -400000
A11: Cash from Investing | B11: =B10 -> -350000 | C11: =C10 -> -180000 | D11: =D10 -> -250000 | E11: =E10 -> -200000 | F11: =F10 -> -300000 | G11: =G10 -> -400000
A13: FINANCING
A14: Equity Investment | B14: =Assumptions!B44 -> 920000 | C14: 0 | D14: 0 | E14: 0 | F14: 0 | G14: 0
A15: Cash from Financing | B15: =B14 -> 920000 | C15: =C14 -> 0 | D15: =D14 -> 0 | E15: =E14 -> 0 | F15: =F14 -> 0 | G15: =G14 -> 0
A17: NET CHANGE IN CASH | B17: =B7+B11+B15 -> 475000 | C17: =C7+C11+C15 -> -740879.32 | D17: =D7+D11+D15 -> -652126.61 | E17: =E7+E11+E15 -> 886096.44 | F17: =F7+F11+F15 -> 4400430.7 | G17: =G7+G11+G15 -> 11263718
A19: Beginning Cash | B19: 0 | C19: =B20 -> 475000 | D19: =C20 -> -265879.32 | E19: =D20 -> -918005.94 | F19: =E20 -> -31909.5 | G19: =F20 -> 4368521.2
A20: Ending Cash | B20: =B19+B17 -> 475000 | C20: =C19+C17 -> -265879.32 | D20: =D19+D17 -> -918005.94 | E20: =E19+E17 -> -31909.5 | F20: =F19+F17 -> 4368521.2 | G20: =G19+G17 -> 15632239

Sheet IRR & Returns
A1: AeroDesk — IRR & Return Analysis
B2: Year 0 | C2: Year 1 | D2: Year 2 | E2: Year 3 | F2: Year 4 | G2: Year 5 | H2: Notes
A3: FREE CASH FLOW
A4: Cash from Ops | B4: ='Cash Flow'!B7 -> -95000 | C4: ='Cash Flow'!C7 -> -560879.32 | D4: ='Cash Flow'!D7 -> -402126.61 | E4: ='Cash Flow'!E7 -> 1086096.4 | F4: ='Cash Flow'!F7 -> 4700430.7 | G4: ='Cash Flow'!G7 -> 11663718
A5: Capex | B5: ='Cash Flow'!B10 -> -350000 | C5: ='Cash Flow'!C10 -> -180000 | D5: ='Cash Flow'!D10 -> -250000 | E5: ='Cash Flow'!E10 -> -200000 | F5: ='Cash Flow'!F10 -> -300000 | G5: ='Cash Flow'!G10 -> -400000
A6: FCFE | B6: =B4+B5 -> -445000 | C6: =C4+C5 -> -740879.32 | D6: =D4+D5 -> -652126.61 | E6: =E4+E5 -> 886096.44 | F6: =F4+F5 -> 4400430.7 | G6: =G4+G5 -> 11263718
A8: INVESTOR RETURNS
A9: Investment (outflow) | B9: =-Assumptions!B44 -> -920000 | C9: 0 | D9: 0 | E9: 0 | F9: 0 | G9: 0
A10: FCFE | B10: =B6 -> -445000 | C10: =C6 -> -740879.32 | D10: =D6 -> -652126.61 | E10: =E6 -> 886096.44 | F10: =F6 -> 4400430.7 | G10: =G6 -> 11263718
A11: Terminal Value (linked exit multiple) | G11: ='Income Statement'!G25*Assumptions!$B$47 -> 160535250
A12: Total CF to Investor | B12: =B9 -> -920000 | C12: =C10 -> -740879.32 | D12: =D10 -> -652126.61 | E12: =E10 -> 886096.44 | F12: =F10 -> 4400430.7 | G12: =G10+G11 -> 1.7179897e+08
A14: IRR | B14: =IRR(B12:G12) -> 1.7189745
A15: Exit Multiple (linked) | B15: =Assumptions!B47 -> 10
A16: MOIC | B16: =IF(-B9=0,0,G11/(-B9)) -> 174.49484
A18: MARKET SHARE
A19: Online TAM (USD M) | C19: =Assumptions!C8 -> 800 | D19: =Assumptions!D8 -> 856 | E19: =Assumptions!E8 -> 916 | F19: =Assumptions!F8 -> 980 | G19: =Assumptions!G8 -> 1048
A20: AeroDesk Rev (USD M) | C20: ='Revenue Detail'!C41/1000000 -> 0.30835 | D20: ='Revenue Detail'!D41/1000000 -> 1.7625 | E20: ='Revenue Detail'!E41/1000000 -> 5.9916 | F20: ='Revenue Detail'!F41/1000000 -> 13.1975 | G20: ='Revenue Detail'!G41/1000000 -> 26.095
A21: Market Share | C21: =IF(C19=0,0,C20/C19) -> 0.0003854375 | D21: =IF(D19=0,0,D20/D19) -> 0.0020589953 | E21: =IF(E19=0,0,E20/E19) -> 0.006541048 | F21: =IF(F19=0,0,F20/F19) -> 0.013466837 | G21: =IF(G19=0,0,G20/G19) -> 0.024899809
A22: Controller.com Est Rev (USD M) | C22: 18.2 | D22: 19 | E22: 19.5 | F22: 20 | G22: 20.5
A23: AeroDesk % of Controller | C23: =IF(C22=0,0,C20/C22) -> 0.016942308 | D23: =IF(D22=0,0,D20/D22) -> 0.092763158 | E23: =IF(E22=0,0,E20/E22) -> 0.30726154 | F23: =IF(F22=0,0,F20/F22) -> 0.659875 | G23: =IF(G22=0,0,G20/G22) -> 1.2729268

Sheet Sensitivity
A1: AeroDesk — Sensitivity Analysis
A3: MOIC SENSITIVITY
A4: Exit Mult / Rev Mult | B4: 0.7 | C4: 0.85 | D4: 1 | E4: 1.15 | F4: 1.3 | G4: Rev Multiplier on Base
A5: 6x | B5: =IFERROR('Income Statement'!G25*0.7*6/Assumptions!$B$44,0) -> 73.287832 | C5: =IFERROR('Income Statement'!G25*0.85*6/Assumptions!$B$44,0) -> 88.992367 | D5: =IFERROR('Income Statement'!G25*1*6/Assumptions!$B$44,0) -> 104.6969 | E5: =IFERROR('Income Statement'!G25*1.15*6/Assumptions!$B$44,0) -> 120.40144 | F5: =IFERROR('Income Statement'!G25*1.3*6/Assumptions!$B$44,0) -> 136.10597
A6: 8x | B6: =IFERROR('Income Statement'!G25*0.7*8/Assumptions!$B$44,0) -> 97.717109 | C6: =IFERROR('Income Statement'!G25*0.85*8/Assumptions!$B$44,0) -> 118.65649 | D6: =IFERROR('Income Statement'!G25*1*8/Assumptions!$B$44,0) -> 139.59587 | E6: =IFERROR('Income Statement'!G25*1.15*8/Assumptions!$B$44,0) -> 160.53525 | F6: =IFERROR('Income Statement'!G25*1.3*8/Assumptions!$B$44,0) -> 181.47463
A7: 10x | B7: =IFERROR('Income Statement'!G25*0.7*10/Assumptions!$B$44,0) -> 122.14639 | C7: =IFERROR('Income Statement'!G25*0.85*10/Assumptions!$B$44,0) -> 148.32061 | D7: =IFERROR('Income Statement'!G25*1*10/Assumptions!$B$44,0) -> 174.49484 | E7: =IFERROR('Income Statement'!G25*1.15*10/Assumptions!$B$44,0) -> 200.66906 | F7: =IFERROR('Income Statement'!G25*1.3*10/Assumptions!$B$44,0) -> 226.84329
A8: 12x | B8: =IFERROR('Income Statement'!G25*0.7*12/Assumptions!$B$44,0) -> 146.57566 | C8: =IFERROR('Income Statement'!G25*0.85*12/Assumptions!$B$44,0) -> 177.98473 | D8: =IFERROR('Income Statement'!G25*1*12/Assumptions!$B$44,0) -> 209.3938 | E8: =IFERROR('Income Statement'!G25*1.15*12/Assumptions!$B$44,0) -> 240.80288 | F8: =IFERROR('Income Statement'!G25*1.3*12/Assumptions!$B$44,0) -> 272.21195
A9: 15x | B9: =IFERROR('Income Statement'!G25*0.7*15/Assumptions!$B$44,0) -> 183.21958 | C9: =IFERROR('Income Statement'!G25*0.85*15/Assumptions!$B$44,0) -> 222.48092 | D9: =IFERROR('Income Statement'!G25*1*15/Assumptions!$B$44,0) -> 261.74226 | E9: =IFERROR('Income Statement'!G25*1.15*15/Assumptions!$B$44,0) -> 301.00359 | F9: =IFERROR('Income Statement'!G25*1.3*15/Assumptions!$B$44,0) -> 340.26493
A12: Y5 SUB REVENUE ($)
A13: Dealers ↓ / Avg Fee → | B13: $250/mo | C13: $300/mo | D13: $340/mo | E13: $400/mo | F13: $450/mo
A14: 600 dealers | B14: 1800000 | C14: 2160000 | D14: 2448000 | E14: 2880000 | F14: 3240000
A15: 800 dealers | B15: 2400000 | C15: 2880000 | D15: 3264000 | E15: 3840000 | F15: 4320000
A16: 1000 dealers | B16: 3000000 | C16: 3600000 | D16: 4080000 | E16: 4800000 | F16: 5400000
A17: 1200 dealers | B17: 3600000 | C17: 4320000 | D17: 4896000 | E17: 5760000 | F17: 6480000
A18: 1500 dealers | B18: 4500000 | C18: 5400000 | D18: 6120000 | E18: 7200000 | F18: 8100000
A21: Y5 EBITDA MARGIN
A22: Gross Margin ↓ / SGA% → | B22: 0.5 | C22: 0.55 | D22: 0.6 | E22: 0.65 | F22: 0.7
A23: 70% GM | B23: 0.2 | C23: 0.15 | D23: 0.1 | E23: 0.05 | F23: 0
A24: 75% GM | B24: 0.25 | C24: 0.2 | D24: 0.15 | E24: 0.1 | F24: 0.05
A25: 80% GM | B25: 0.3 | C25: 0.25 | D25: 0.2 | E25: 0.15 | F25: 0.1
A26: 85% GM | B26: 0.35 | C26: 0.3 | D26: 0.25 | E26: 0.2 | F26: 0.15
A27: 90% GM | B27: 0.4 | C27: 0.35 | D27: 0.3 | E27: 0.25 | F27: 0.2

Sheet Dashboard
A1: AeroDesk — Visual Dashboard
A3: Year | B3: Y0 | C3: Y1 | D3: Y2 | E3: Y3 | F3: Y4 | G3: Y5
A4: Revenue | B4: ='Income Statement'!B4 -> 0 | C4: ='Income Statement'!C4 -> 308350 | D4: ='Income Statement'!D4 -> 1762500 | E4: ='Income Statement'!E4 -> 5991600 | F4: ='Income Statement'!F4 -> 13197500 | G4: ='Income Statement'!G4 -> 26095000
A5: COGS | B5: ='Income Statement'!B11 -> 6000 | C5: ='Income Statement'!C11 -> 67708.75 | D5: ='Income Statement'!D11 -> 170062.5 | E5: ='Income Statement'!E11 -> 365790 | F5: ='Income Statement'!F11 -> 689937.5 | G5: ='Income Statement'!G11 -> 1216375
A6: Gross Profit | B6: ='Income Statement'!B12 -> -6000 | C6: ='Income Statement'!C12 -> 240641.25 | D6: ='Income Statement'!D12 -> 1592437.5 | E6: ='Income Statement'!E12 -> 5625810 | F6: ='Income Statement'!F12 -> 12507562 | G6: ='Income Statement'!G12 -> 24878625
A7: SG&A | B7: ='Income Statement'!B23 -> 59000 | C7: ='Income Statement'!C23 -> 763592.5 | D7: ='Income Statement'!D23 -> 1795000 | E7: ='Income Statement'!E23 -> 3613480 | F7: ='Income Statement'!F23 -> 5699450 | G7: ='Income Statement'!G23 -> 8825100
A8: EBITDA | B8: ='Income Statement'!B25 -> -65000 | C8: ='Income Statement'!C25 -> -522951.25 | D8: ='Income Statement'!D25 -> -202562.5 | E8: ='Income Statement'!E25 -> 2012330 | F8: ='Income Statement'!F25 -> 6808112.5 | G8: ='Income Statement'!G25 -> 16053525
A9: Net Income | B9: ='Income Statement'!B33 -> -65000 | C9: ='Income Statement'!C33 -> -558951.25 | D9: ='Income Statement'!D33 -> -252562.5 | E9: ='Income Statement'!E33 -> 1676480.5 | F9: ='Income Statement'!F33 -> 5735895.6 | G9: ='Income Statement'!G33 -> 13577496
A10: Capex | B10: =Assumptions!B43 -> 350000 | C10: =Assumptions!C43 -> 180000 | D10: =Assumptions!D43 -> 250000 | E10: =Assumptions!E43 -> 200000 | F10: =Assumptions!F43 -> 300000 | G10: =Assumptions!G43 -> 400000
A11: FCFE | B11: ='IRR & Returns'!B6 -> -445000 | C11: ='IRR & Returns'!C6 -> -740879.32 | D11: ='IRR & Returns'!D6 -> -652126.61 | E11: ='IRR & Returns'!E6 -> 886096.44 | F11: ='IRR & Returns'!F6 -> 4400430.7 | G11: ='IRR & Returns'!G6 -> 11263718
A12: Cash Balance | B12: ='Balance Sheet'!B4 -> 475000 | C12: ='Balance Sheet'!C4 -> -265879.32 | D12: ='Balance Sheet'!D4 -> -918005.94 | E12: ='Balance Sheet'!E4 -> -31909.5 | F12: ='Balance Sheet'!F4 -> 4368521.2 | G12: ='Balance Sheet'!G4 -> 15632239
A14: Gross Margin % | C14: =IF(C4=0,0,C6/C4) -> 0.78041592 | D14: =IF(D4=0,0,D6/D4) -> 0.90351064 | E14: =IF(E4=0,0,E6/E4) -> 0.93894953 | F14: =IF(F4=0,0,F6/F4) -> 0.94772211 | G14: =IF(G4=0,0,G6/G4) -> 0.95338666
A15: EBITDA Margin % | C15: =IF(C4=0,0,C8/C4) -> -1.6959664 | D15: =IF(D4=0,0,D8/D4) -> -0.11492908 | E15: =IF(E4=0,0,E8/E4) -> 0.33585854 | F15: =IF(F4=0,0,F8/F4) -> 0.5158638 | G15: =IF(G4=0,0,G8/G4) -> 0.61519544
A16: Net Margin % | C16: =IF(C4=0,0,C9/C4) -> -1.8127169 | D16: =IF(D4=0,0,D9/D4) -> -0.14329787 | E16: =IF(E4=0,0,E9/E4) -> 0.27980514 | F16: =IF(F4=0,0,F9/F4) -> 0.43461986 | G16: =IF(G4=0,0,G9/G4) -> 0.52031026
A67: Revenue by Stream (Y5)
B68: Dealer Subs | C68: Featured | D68: Individual | E68: Txn Comm | F68: Ancillary | G68: Data | H68: Mkt/Ads
B69: ='Revenue Detail'!G6 -> 4080000 | C69: ='Revenue Detail'!G11 -> 1925000 | D69: ='Revenue Detail'!G16 -> 840000 | E69: ='Revenue Detail'!G22 -> 11550000 | F69: ='Revenue Detail'!G28 -> 2030000 | G69: ='Revenue Detail'!G33 -> 1890000 | H69: ='Revenue Detail'!G38 -> 3780000
